Workbook

Sheet Datos_Cliente
B4: NO. DE SOLICITUD: | C4: 2025-0482 | F4: NO. REPORTE | G4: 0034
B5: RECEPCIÓN: | C5: 45922 | F5: UBICACIÓN: | G5: BACUM, SON.
B6: NOMBRE DEL CLIENTE: | C6: EL CAUDILLO | F6: PREDIO: | G6: BLOCK 905
B7: EMPRESA: | C7: EL CAUDILLO | F7: CULTIVO ANTERIOR: | G7: NOGAL
B8: NO. DE MUESTRAS: | C8: 6 | F8: CULTIVO ESTABLECIDO/ER: | G8: NOGAL
F9: ETAPA: | G9: COSECHA
B10: MUESTRA DEL CLIENTE | C10: MUESTRA DE LABORATORIO | F10: FOLIO:
A11: 1 | B11: 50 HAS 2012 NORTE | C11: 2025-0482-1 | F11: TIPO DE RIEGO: | G11: GOTEO
A12: 2 | B12: 50 HAS 2012 SUR | C12: 2025-0482-2 | F12: FECHA DE ANÁLISIS:
A13: 3 | B13: 25 HAS 2014 SUR | C13: 2025-0482-3 | F13: FECHA DE RESULTADOS:
A14: 4 | B14: 25 HAS 2014 NORTE | C14: 2025-0482-4 | F14: FECHA DE CAPTURA: | G14: 45924
A15: 5 | B15: 25 HAS 2015 NORTE | C15: 2025-0482-5 | F15: RECOMENDACION: | G15: 45926
A16: 6 | B16: 25 HAS 2015 SUR | C16: 2025-0482-6 | E16: etapa/cultivo | G16: Nogal/Hojas maduras de ramas vegetativas
A17: 7
A18: 8
A19: 9
A20: 10
A21: 11
A22: 12
A23: 13
A24: 14
A25: 15
A26: 16
A27: 17
A28: 18
... A30: 20

Sheet Lectura_Fert
B3: PLANTAS
H6: Macronutrientes
K7: Nitrógeno total
B8: NORMAILIDAD | C8: NA | D8: NA | E8: NA | F8: NA | G8: Boro | H8: Fósforo (P) aprovechable | K8: 0.1 | M8: Nitrógeno nítrico (N-NO3) | R8: Absorción atómica | T8: Emisión de flama
B9: NO. LAB | C9: Cu | D9: Mn | E9: Fe | F9: Zn | G9: B (%T) | H9: Peso (g) | I9: Alícuota (ml) | J9: Transmitancia (%) | K9: Muestra (gr) | L9: HCL gastado | M9: Peso (g) | N9: Dilución1 (ml) | O9: Alícuota (ml) | P9: Dilución2 (ml) | Q9: (N-NO3) (%T) | R9: Ca (mg/L) | S9: Mg (mg/L) | T9: Factor de dilución 1 | U9: Factor de dilución 2 | V9: Muestra (mg/L) | W9: Na (ppm) | X9: Muestra (ml) | Y9: K (ppm)
B10: 0 (BLANCO) | C10: NA | D10: NA | E10: NA | F10: NA | G10: NA | H10: NA | I10: NA | J10: NA | K10: NA | L10: NA | M10: NA | N10: NA | O10: NA | P10: NA | Q10: NA | R10: NA | S10: NA | T10: NA | U10: NA | V10: NA | X10: NA | Y10: 0
B11: =Datos_Cliente!C11 -> 2025-0482-1 | C11: 4.88 | D11: 657.22 | E11: 168.71 | F11: 82.26 | G11: 52 | H11: 1 | I11: 10 | J11: 89.5 | K11: 0.1 | L11: 1.85 | M11: 0.1 | N11: 25 | O11: 2 | P11: 100 | R11: 3.02 | S11: 0.63 | T11: 100 | U11: 20 | X11: 1 | Y11: 4.4
B12: =Datos_Cliente!C12 -> 2025-0482-2 | C12: 4.89 | D12: 563.95 | E12: 162.48 | F12: 116.87 | G12: 62 | H12: 1 | I12: 10 | J12: 90 | K12: 0.1 | L12: 1.8 | R12: 2.57 | S12: 0.55 | T12: 100 | U12: 20 | X12: 1 | Y12: 4
B13: =Datos_Cliente!C13 -> 2025-0482-3 | C13: 4.8 | D13: 583.2 | E13: 168.46 | F13: 120.3 | G13: 60 | H13: 1 | I13: 10 | J13: 88.5 | K13: 0.1 | L13: 1.7 | R13: 2.63 | S13: 0.54 | T13: 100 | U13: 20 | X13: 1 | Y13: 4
B14: =Datos_Cliente!C14 -> 2025-0482-4 | C14: 4.24 | D14: 614.38 | E14: 158.89 | F14: 131.62 | G14: 55 | H14: 1 | I14: 10 | J14: 89 | K14: 0.1 | L14: 1.9 | R14: 3.08 | S14: 0.66 | T14: 100 | U14: 20 | X14: 1 | Y14: 4.1
B15: =Datos_Cliente!C15 -> 2025-0482-5 | C15: 4.31 | D15: 620.44 | E15: 160.89 | F15: 116.32 | G15: 57 | H15: 1 | I15: 10 | J15: 89 | K15: 0.1 | L15: 1.85 | R15: 2.45 | S15: 0.57 | T15: 100 | U15: 20 | X15: 1 | Y15: 3.8
B16: =Datos_Cliente!C16 -> 2025-0482-6 | C16: 7.65 | D16: 554.73 | E16: 125.92 | F16: 109.57 | G16: 59.5 | H16: 1 | I16: 10 | J16: 90 | K16: 0.1 | L16: 1.75 | R16: 2.39 | S16: 0.59 | T16: 100 | U16: 20 | X16: 1 | Y16: 3.5
B17: =Datos_Cliente!C17 -> 0
B18: =Datos_Cliente!C18 -> 0
B19: =Datos_Cliente!C19 -> 0
B20: =Datos_Cliente!C20 -> 0
B21: =Datos_Cliente!C21 -> 0
B22: =Datos_Cliente!C22 -> 0
B23: =Datos_Cliente!C23 -> 0
B24: =Datos_Cliente!C24 -> 0
B25: =Datos_Cliente!C25 -> 0
B26: =Datos_Cliente!C26 -> 0
B27: =Datos_Cliente!C27 -> 0
B28: =Datos_Cliente!C28 -> 0
... B30: =Datos_Cliente!C30 -> 0

Sheet Factores
B3: 3.2.1
B4: 3.2.2
B5: 3.2.3
B6: 3.2.4 | C6: 5 | D6: 1 | E6: =12/4000 -> 0.003 | F6: =1.724/0.77 -> 2.238961 | G6: 100
B7: 3.2.5 | C7: 0.09947
B8: 3.2.6 | C8: 0.25 | D8: 2.5
B9: 3.2.7 | C9: 19.4 | D9: 0.36 | E9: 100 | F9: 2
B10: 3.2.8
B11: 3.2.9 | C11: 1.84 | D11: 0.48
B12: 3.2.10 | C12: 0.595
B13: 3.2.11
B14: 3.2.12 | C14: 1
B15: 3.2.13 | C15: 1 | D15: 99.409 | E15: 9.4091
B16: 3.2.14 | C16: 1 | D16: 0.001 | E16: 0.4956
B17: 3.2.15 | C17: 70 | D17: 23.3 | E17: 0.0191 | F17: 0.0005 | G17: 0.2147
B18: 3.2.16 | C18: 1 | D18: 1 | E18: 1
B19: 3.2.17
B20: 3.2.18
B21: 3.2.19
B22: 3.2.22 | C22: 48
B23: 3.2.23 | C23: 2 | D23: 99.409 | E23: 9.4091
B24: 3.2.24
B25: 3.2.25
B26: 3.2.26 | C26: 23 | D26: 1 | E26: 1
B27: 3.2.27 | C27: 39 | D27: 1 | E27: 1
B28: 3.2.28
B29: 3.2.29
B30: 3.2.30 | C30: 1 | D30: 0.001 | E30: 0.4956
B31: 3.2.31 | C31: 10 | D31: 3.33 | E31: 1.42 | F31: 0.0019 | G31: 0.2147
B32: 3.2.32 | C32: 1

Sheet Boro
A1: %T | B1: Absorbancia | C1: PPM_BORO_curva | D1: ppm_BORO
A2: 4 | B2: =(-LOG(A2/100)) -> 1.39794 | C2: =((B2-$G$15)/$G$16) -> 2.3146786 | D2: =C2*400 -> 925.87144 | G2: ml de sol. 10ppm | H2: concentracion de Boro | I2: concentracion de Boro ajustada | J2: absorbancia
A3: 4.5 | B3: =(-LOG(A3/100)) -> 1.3467875 | C3: =((B3-$G$15)/$G$16) -> 2.2299329 | D3: =C3*400 -> 891.97315
A4: 5 | B4: =(-LOG(A4/100)) -> 1.30103 | C4: =((B4-$G$15)/$G$16) -> 2.1541252 | D4: =C4*400 -> 861.6501 | G4: 0 | H4: 0 | I4: 0 | J4: 0
A5: 5.5 | B5: =(-LOG(A5/100)) -> 1.2596373 | C5: =((B5-$G$15)/$G$16) -> 2.0855489 | D5: =C5*400 -> 834.21956 | G5: 2 | H5: 0.2 | I5: 0.05 | J5: 0.036
A6: 6 | B6: =(-LOG(A6/100)) -> 1.2218487 | C6: =((B6-$G$15)/$G$16) -> 2.0229436 | D6: =C6*400 -> 809.17744 | G6: 4 | H6: 0.4 | I6: 0.1 | J6: 0.055
A7: 6.5 | B7: =(-LOG(A7/100)) -> 1.1870866 | C7: =((B7-$G$15)/$G$16) -> 1.9653523 | D7: =C7*400 -> 786.14092 | G7: 6 | H7: 0.6 | I7: 0.15 | J7: 0.086
A8: 7 | B8: =(-LOG(A8/100)) -> 1.154902 | C8: =((B8-$G$15)/$G$16) -> 1.9120311 | D8: =C8*400 -> 764.81243 | G8: 8 | H8: 0.8 | I8: 0.2 | J8: 0.131
A9: 7.5 | B9: =(-LOG(A9/100)) -> 1.1249387 | C9: =((B9-$G$15)/$G$16) -> 1.8623902 | D9: =C9*400 -> 744.95609 | G9: 10 | H9: 1 | I9: 0.25 | J9: 0.149
A10: 8 | B10: =(-LOG(A10/100)) -> 1.09691 | C10: =((B10-$G$15)/$G$16) -> 1.8159543 | D10: =C10*400 -> 726.38172 | G10: 15 | H10: 1.5 | I10: 0.375 | J10: 0.229
A11: 8.5 | B11: =(-LOG(A11/100)) -> 1.0705811 | C11: =((B11-$G$15)/$G$16) -> 1.7723345 | D11: =C11*400 -> 708.93378 | G11: 20 | H11: 2 | I11: 0.5 | J11: 0.301
A12: 9 | B12: =(-LOG(A12/100)) -> 1.0457575 | C12: =((B12-$G$15)/$G$16) -> 1.7312086 | D12: =C12*400 -> 692.48343
A13: 9.5 | B13: =(-LOG(A13/100)) -> 1.0222764 | C13: =((B13-$G$15)/$G$16) -> 1.6923068 | D13: =C13*400 -> 676.92273
A14: 10 | B14: =(-LOG(A14/100)) -> 1 | C14: =((B14-$G$15)/$G$16) -> 1.6554009 | D14: =C14*400 -> 662.16037
A15: 10.5 | B15: =(-LOG(A15/100)) -> 0.9788107 | C15: =((B15-$G$15)/$G$16) -> 1.6202961 | D15: =C15*400 -> 648.11842 | E15: x= | F15: y- | G15: 0.0008
A16: 11 | B16: =(-LOG(A16/100)) -> 0.95860731 | C16: =((B16-$G$15)/$G$16) -> 1.5868246 | D16: =C16*400 -> 634.72983 | G16: 0.6036
A17: 11.5 | B17: =(-LOG(A17/100)) -> 0.93930216 | C17: =((B17-$G$15)/$G$16) -> 1.5548412 | D17: =C17*400 -> 621.93649
A18: 12 | B18: =(-LOG(A18/100)) -> 0.92081875 | C18: =((B18-$G$15)/$G$16) -> 1.5242193 | D18: =C18*400 -> 609.68771
A19: 12.5 | B19: =(-LOG(A19/100)) -> 0.90308999 | C19: =((B19-$G$15)/$G$16) -> 1.4948476 | D19: =C19*400 -> 597.93902
A20: 13 | B20: =(-LOG(A20/100)) -> 0.88605665 | C20: =((B20-$G$15)/$G$16) -> 1.466628 | D20: =C20*400 -> 586.65119
A21: 13.5 | B21: =(-LOG(A21/100)) -> 0.86966623 | C21: =((B21-$G$15)/$G$16) -> 1.4394735 | D21: =C21*400 -> 575.78942
A22: 14 | B22: =(-LOG(A22/100)) -> 0.85387196 | C22: =((B22-$G$15)/$G$16) -> 1.4133068 | D22: =C22*400 -> 565.32271
A23: 14.5 | B23: =(-LOG(A23/100)) -> 0.838632 | C23: =((B23-$G$15)/$G$16) -> 1.3880583 | D23: =C23*400 -> 555.22333
A24: 15 | B24: =(-LOG(A24/100)) -> 0.82390874 | C24: =((B24-$G$15)/$G$16) -> 1.3636659 | D24: =C24*400 -> 545.46636
A25: 15.5 | B25: =(-LOG(A25/100)) -> 0.8096683 | C25: =((B25-$G$15)/$G$16) -> 1.3400734 | D25: =C25*400 -> 536.02936
A26: 16 | B26: =(-LOG(A26/100)) -> 0.79588002 | C26: =((B26-$G$15)/$G$16) -> 1.31723 | D26: =C26*400 -> 526.89199
A27: 16.5 | B27: =(-LOG(A27/100)) -> 0.78251606 | C27: =((B27-$G$15)/$G$16) -> 1.2950896 | D27: =C27*400 -> 518.03582
A28: 17 | B28: =(-LOG(A28/100)) -> 0.76955108 | C28: =((B28-$G$15)/$G$16) -> 1.2736101 | D28: =C28*400 -> 509.44405
... A189: 97.5 | B189: =(-LOG(A189/100)) -> 0.010995384 | C189: =((B189-$G$15)/$G$16) -> 0.016890961 | D189: =C189*400 -> 6.7563846
A190: 98 | B190: 0.009 | C190: =((B190-$G$15)/$G$16) -> 0.013585156 | D190: =C190*400 -> 5.4340623
A191: 98.5 | B191: =(-LOG(A191/100)) -> 0.0065637695 | C191: =((B191-$G$15)/$G$16) -> 0.0095489886 | D191: =C191*400 -> 3.8195954
A192: 99 | B192: =(-LOG(A192/100)) -> 0.0043648054 | C192: =((B192-$G$15)/$G$16) -> 0.0059059069 | D192: =C192*400 -> 2.3623628
A193: 99.5 | B193: =(-LOG(A193/100)) -> 0.0021769193 | C193: =((B193-$G$15)/$G$16) -> 0.0022811784 | D193: =C193*400 -> 0.91247134
A194: 100 | B194: =(-LOG(A194/100)) -> 0 | C194: 0 | D194: =C194*400 -> 0

Sheet N_Total

Sheet N-NO3
A1: %TRANS_N-NO3 | B1: PPM_N-NO3 | C1: absorbancia | D1: alicuota de 2ml | E1: alicuota de 3ml | F1: alicuota de 4ml | G1: alicuota de 5ml
A2: 7.5 | B2: =(C2-$K$18)/$J$19 -> 2.6278942 | C2: =(-(LOG(A2/100))) -> 1.1249387 | D2: =(B2*$J$21)/1000 -> 32.848678 | E2: =B2*$J$22 -> 87.595599 | F2: =B2*$J$23 -> 65.697356 | G2: =B2*$J$24 -> 52.557885
A3: 8 | B3: =(C3-$K$18)/$J$19 -> 2.5624066 | C3: =(-(LOG(A3/100))) -> 1.09691 | D3: =B3*$J$21 -> 32030.082 | E3: =B3*$J$22 -> 85.412698 | F3: =B3*$J$23 -> 64.060164 | G3: =B3*$J$24 -> 51.248131
A4: 8.5 | B4: =(C4-$K$18)/$J$19 -> 2.5008904 | C4: =(-(LOG(A4/100))) -> 1.0705811 | D4: =B4*$J$21 -> 31261.13 | E4: =B4*$J$22 -> 83.362178 | F4: =B4*$J$23 -> 62.522259 | G4: =B4*$J$24 -> 50.017807
A5: 9 | B5: =(C5-$K$18)/$J$19 -> 2.4428913 | C5: =(-(LOG(A5/100))) -> 1.0457575 | D5: =B5*$J$21 -> 30536.142 | E5: =B5*$J$22 -> 81.428897 | F5: =B5*$J$23 -> 61.072283 | G5: =B5*$J$24 -> 48.857827
A6: 9.5 | B6: =(C6-$K$18)/$J$19 -> 2.388029 | C6: =(-(LOG(A6/100))) -> 1.0222764 | D6: =B6*$J$21 -> 29850.362 | E6: =B6*$J$22 -> 79.600169 | F6: =B6*$J$23 -> 59.700724 | G6: =B6*$J$24 -> 47.760579
A7: 10 | B7: =(C7-$K$18)/$J$19 -> 2.3359813 | C7: =(-(LOG(A7/100))) -> 1 | D7: =B7*$J$21 -> 29199.766 | E7: =B7*$J$22 -> 77.865265 | F7: =B7*$J$23 -> 58.399533 | G7: =B7*$J$24 -> 46.719626
A8: 10.5 | B8: =(C8-$K$18)/$J$19 -> 2.2864736 | C8: =(-(LOG(A8/100))) -> 0.9788107 | D8: =B8*$J$21 -> 28580.92 | E8: =B8*$J$22 -> 76.215025 | F8: =B8*$J$23 -> 57.16184 | G8: =B8*$J$24 -> 45.729472
A9: 11 | B9: =(C9-$K$18)/$J$19 -> 2.2392694 | C9: =(-(LOG(A9/100))) -> 0.95860731 | D9: =B9*$J$21 -> 27990.868 | E9: =B9*$J$22 -> 74.641568 | F9: =B9*$J$23 -> 55.981736 | G9: =B9*$J$24 -> 44.785389
A10: 11.5 | B10: =(C10-$K$18)/$J$19 -> 2.1941639 | C10: =(-(LOG(A10/100))) -> 0.93930216 | D10: =B10*$J$21 -> 27427.049 | E10: =B10*$J$22 -> 73.138066 | F10: =B10*$J$23 -> 54.854098 | G10: =B10*$J$24 -> 43.883278
A11: 12 | B11: =(C11-$K$18)/$J$19 -> 2.1509784 | C11: =(-(LOG(A11/100))) -> 0.92081875 | D11: =B11*$J$21 -> 26887.23 | E11: =B11*$J$22 -> 71.698563 | F11: =B11*$J$23 -> 53.77446 | G11: =B11*$J$24 -> 43.019568
A12: 12.5 | B12: =(C12-$K$18)/$J$19 -> 2.109556 | C12: =(-(LOG(A12/100))) -> 0.90308999 | D12: =B12*$J$21 -> 26369.451 | E12: =B12*$J$22 -> 70.317832 | F12: =B12*$J$23 -> 52.738901 | G12: =B12*$J$24 -> 42.191121
A13: 13 | B13: =(C13-$K$18)/$J$19 -> 2.0697585 | C13: =(-(LOG(A13/100))) -> 0.88605665 | D13: =B13*$J$21 -> 25871.982 | E13: =B13*$J$22 -> 68.991261 | F13: =B13*$J$23 -> 51.743963 | G13: =B13*$J$24 -> 41.39517
A14: 13.5 | B14: =(C14-$K$18)/$J$19 -> 2.0314632 | C14: =(-(LOG(A14/100))) -> 0.86966623 | D14: =B14*$J$21 -> 25393.289 | E14: =B14*$J$22 -> 67.714761 | F14: =B14*$J$23 -> 50.786579 | G14: =B14*$J$24 -> 40.629263
... A17: 15 | B17: =(C17-$K$18)/$J$19 -> 1.9245531 | C17: =(-(LOG(A17/100))) -> 0.82390874 | D17: =B17*$J$21 -> 24056.914 | E17: =B17*$J$22 -> 64.15113 | F17: =B17*$J$23 -> 48.113828 | G17: =B17*$J$24 -> 38.491063
A18: 15.5 | B18: =(C18-$K$18)/$J$19 -> 1.8912811 | C18: =(-(LOG(A18/100))) -> 0.8096683 | D18: =B18*$J$21 -> 23641.013 | E18: =B18*$J$22 -> 63.042072 | F18: =B18*$J$23 -> 47.282027 | G18: =B18*$J$24 -> 37.825622 | I18: x= | J18: y- | K18: 0.0002 | M18: 0.0002
A19: 16 | B19: =(C19-$K$18)/$J$19 -> 1.8590655 | C19: =(-(LOG(A19/100))) -> 0.79588002 | D19: =B19*$J$21 -> 23238.318 | E19: =B19*$J$22 -> 61.968229 | F19: =B19*$J$23 -> 46.476637 | G19: =B19*$J$24 -> 37.181309 | J19: 0.428 | M19: 0.428
A20: 16.5 | B20: =(C20-$K$18)/$J$19 -> 1.8278413 | C20: =(-(LOG(A20/100))) -> 0.78251606 | D20: =B20*$J$21 -> 22848.016 | E20: =B20*$J$22 -> 60.927432 | F20: =B20*$J$23 -> 45.696031 | G20: =B20*$J$24 -> 36.556825
A21: 17 | B21: =(C21-$K$18)/$J$19 -> 1.7975492 | C21: =(-(LOG(A21/100))) -> 0.76955108 | D21: =B21*$J$21 -> 22469.366 | E21: =B21*$J$22 -> 59.917709 | F21: =B21*$J$23 -> 44.938731 | G21: =B21*$J$24 -> 35.950985 | I21: 2ml | J21: 12500
A22: 17.5 | B22: =(C22-$K$18)/$J$19 -> 1.7681354 | C22: =(-(LOG(A22/100))) -> 0.75696195 | D22: =B22*$J$21 -> 22101.693 | E22: =B22*$J$22 -> 58.937257 | F22: =B22*$J$23 -> 44.203385 | G22: =B22*$J$24 -> 35.362708 | I22: 3ml | J22: 33.333
A23: 18 | B23: =(C23-$K$18)/$J$19 -> 1.7395502 | C23: =(-(LOG(A23/100))) -> 0.74472749 | D23: =B23*$J$21 -> 21744.378 | E23: =B23*$J$22 -> 57.984428 | F23: =B23*$J$23 -> 43.488756 | G23: =B23*$J$24 -> 34.791004 | I23: 4ml | J23: 25
A24: 18.5 | B24: =(C24-$K$18)/$J$19 -> 1.7117483 | C24: =(-(LOG(A24/100))) -> 0.73282827 | D24: =B24*$J$21 -> 21396.854 | E24: =B24*$J$22 -> 57.057706 | F24: =B24*$J$23 -> 42.793707 | G24: =B24*$J$24 -> 34.234966 | I24: 5ml | J24: 20
A25: 19 | B25: =(C25-$K$18)/$J$19 -> 1.6846878 | C25: =(-(LOG(A25/100))) -> 0.7212464 | D25: =B25*$J$21 -> 21058.598 | E25: =B25*$J$22 -> 56.1557 | F25: =B25*$J$23 -> 42.117196 | G25: =B25*$J$24 -> 33.693757
A26: 19.5 | B26: =(C26-$K$18)/$J$19 -> 1.6583303 | C26: =(-(LOG(A26/100))) -> 0.70996539 | D26: =B26*$J$21 -> 20729.129 | E26: =B26*$J$22 -> 55.277125 | F26: =B26*$J$23 -> 41.458259 | G26: =B26*$J$24 -> 33.166607
A27: 20 | B27: =(C27-$K$18)/$J$19 -> 1.6326402 | C27: =(-(LOG(A27/100))) -> 0.69897 | D27: =B27*$J$21 -> 20408.002 | E27: =B27*$J$22 -> 54.420796 | F27: =B27*$J$23 -> 40.816005 | G27: =B27*$J$24 -> 32.652804
A28: 20.5 | B28: =(C28-$K$18)/$J$19 -> 1.6075844 | C28: =(-(LOG(A28/100))) -> 0.68824614 | D28: =B28*$J$21 -> 20094.805 | E28: =B28*$J$22 -> 53.585612 | F28: =B28*$J$23 -> 40.189611 | G28: =B28*$J$24 -> 32.151689
A29: 21 | B29: =(C29-$K$18)/$J$19 -> 1.5831325 | C29: =(-(LOG(A29/100))) -> 0.67778071 | D29: =B29*$J$21 -> 19789.156 | E29: =B29*$J$22 -> 52.770555 | F29: =B29*$J$23 -> 39.578312 | G29: =B29*$J$24 -> 31.66265
A30: 21.5 | B30: =(C30-$K$18)/$J$19 -> 1.5592559 | C30: =(-(LOG(A30/100))) -> 0.66756154 | D30: =B30*$J$21 -> 19490.699 | E30: =B30*$J$22 -> 51.974678 | F30: =B30*$J$23 -> 38.981398 | G30: =B30*$J$24 -> 31.185119
A31: 22 | B31: =(C31-$K$18)/$J$19 -> 1.5359283 | C31: =(-(LOG(A31/100))) -> 0.65757732 | D31: =B31*$J$21 -> 19199.104 | E31: =B31*$J$22 -> 51.197099 | F31: =B31*$J$23 -> 38.398208 | G31: =B31*$J$24 -> 30.718566
A32: 22.5 | B32: =(C32-$K$18)/$J$19 -> 1.513125 | C32: =(-(LOG(A32/100))) -> 0.64781748 | D32: =B32*$J$21 -> 18914.062 | E32: =B32*$J$22 -> 50.436994 | F32: =B32*$J$23 -> 37.828124 | G32: =B32*$J$24 -> 30.262499
A33: 23 | B33: =(C33-$K$18)/$J$19 -> 1.4908228 | C33: =(-(LOG(A33/100))) -> 0.63827216 | D33: =B33*$J$21 -> 18635.285 | E33: =B33*$J$22 -> 49.693597 | F33: =B33*$J$23 -> 37.27057 | G33: =B33*$J$24 -> 29.816456
A34: 23.5 | B34: =(C34-$K$18)/$J$19 -> 1.4690003 | C34: =(-(LOG(A34/100))) -> 0.62893214 | D34: =B34*$J$21 -> 18362.504 | E34: =B34*$J$22 -> 48.966188 | F34: =B34*$J$23 -> 36.725008 | G34: =B34*$J$24 -> 29.380006
A35: 24 | B35: =(C35-$K$18)/$J$19 -> 1.4476373 | C35: =(-(LOG(A35/100))) -> 0.61978876 | D35: =B35*$J$21 -> 18095.466 | E35: =B35*$J$22 -> 48.254094 | F35: =B35*$J$23 -> 36.190932 | G35: =B35*$J$24 -> 28.952746
A36: 24.5 | B36: =(C36-$K$18)/$J$19 -> 1.4267148 | C36: =(-(LOG(A36/100))) -> 0.61083392 | D36: =B36*$J$21 -> 17833.934 | E36: =B36*$J$22 -> 47.556683 | F36: =B36*$J$23 -> 35.667869 | G36: =B36*$J$24 -> 28.534295
... A187: 100 | B187: =(C187-$K$18)/$J$19 -> -0.00046728972 | C187: =(-(LOG(A187/100))) -> 0 | D187: =B187*$J$21 -> -5.8411215 | E187: =B187*$J$22 -> -0.015576168 | F187: =B187*$J$23 -> -0.011682243 | G187: =B187*$J$24 -> -0.0093457944

Sheet P_Aprov
A1: %TRANS_P | B1: PPM_CURVA_P | C1: absorbancia | D1: % P
A2: 4.5 | B2: =(C2+$H$19)/$G$20 -> 69.849093 | C2: =(-(LOG(A2/100))) -> 1.3467875 | D2: =(500*B2)/10000 -> 3.4924546
A3: 5 | B3: =(C3+$H$19)/$G$20 -> 67.478238 | C3: =(-(LOG(A3/100))) -> 1.30103 | D3: =(500*B3)/10000 -> 3.3739119
A4: 5.5 | B4: =(C4+$H$19)/$G$20 -> 65.333539 | C4: =(-(LOG(A4/100))) -> 1.2596373 | D4: =(500*B4)/10000 -> 3.266677
A5: 6 | B5: =(C5+$H$19)/$G$20 -> 63.375583 | C5: =(-(LOG(A5/100))) -> 1.2218487 | D5: =(500*B5)/10000 -> 3.1687791
A6: 6.5 | B6: =(C6+$H$19)/$G$20 -> 61.574437 | C6: =(-(LOG(A6/100))) -> 1.1870866 | D6: =(500*B6)/10000 -> 3.0787219
A7: 7 | B7: =(C7+$H$19)/$G$20 -> 59.906837 | C7: =(-(LOG(A7/100))) -> 1.154902 | D7: =(500*B7)/10000 -> 2.9953419
A8: 7.5 | B8: =(C8+$H$19)/$G$20 -> 58.354339 | C8: =(-(LOG(A8/100))) -> 1.1249387 | D8: =(500*B8)/10000 -> 2.9177169
A9: 8 | B9: =(C9+$H$19)/$G$20 -> 56.902073 | C9: =(-(LOG(A9/100))) -> 1.09691 | D9: =(500*B9)/10000 -> 2.8451037
A10: 8.5 | B10: =(C10+$H$19)/$G$20 -> 55.537879 | C10: =(-(LOG(A10/100))) -> 1.0705811 | D10: =(500*B10)/10000 -> 2.776894
A11: 9 | B11: =(C11+$H$19)/$G$20 -> 54.251683 | C11: =(-(LOG(A11/100))) -> 1.0457575 | D11: =(500*B11)/10000 -> 2.7125842
A12: 9.5 | B12: =(C12+$H$19)/$G$20 -> 53.035046 | C12: =(-(LOG(A12/100))) -> 1.0222764 | D12: =(500*B12)/10000 -> 2.6517523
A13: 10 | B13: =(C13+$H$19)/$G$20 -> 51.880829 | C13: =(-(LOG(A13/100))) -> 1 | D13: =(500*B13)/10000 -> 2.5940415
... A18: 12.5 | B18: =(C18+$H$19)/$G$20 -> 46.859585 | C18: =(-(LOG(A18/100))) -> 0.90308999 | D18: =(500*B18)/10000 -> 2.3429792
A19: 13 | B19: =(C19+$H$19)/$G$20 -> 45.977028 | C19: =(-(LOG(A19/100))) -> 0.88605665 | D19: =(500*B19)/10000 -> 2.2988514 | F19: x= | G19: y+ | H19: 0.0013
A20: 13.5 | B20: =(C20+$H$19)/$G$20 -> 45.127784 | C20: =(-(LOG(A20/100))) -> 0.86966623 | D20: =(500*B20)/10000 -> 2.2563892 | G20: 0.0193
A21: 14 | B21: =(C21+$H$19)/$G$20 -> 44.309428 | C21: =(-(LOG(A21/100))) -> 0.85387196 | D21: =(500*B21)/10000 -> 2.2154714
A22: 14.5 | B22: =(C22+$H$19)/$G$20 -> 43.519793 | C22: =(-(LOG(A22/100))) -> 0.838632 | D22: =(500*B22)/10000 -> 2.1759896
A23: 15 | B23: =(C23+$H$19)/$G$20 -> 42.75693 | C23: =(-(LOG(A23/100))) -> 0.82390874 | D23: =(500*B23)/10000 -> 2.1378465
A24: 15.5 | B24: =(C24+$H$19)/$G$20 -> 42.019083 | C24: =(-(LOG(A24/100))) -> 0.8096683 | D24: =(500*B24)/10000 -> 2.1009541
A25: 16 | B25: =(C25+$H$19)/$G$20 -> 41.304664 | C25: =(-(LOG(A25/100))) -> 0.79588002 | D25: =(500*B25)/10000 -> 2.0652332
A26: 16.5 | B26: =(C26+$H$19)/$G$20 -> 40.612231 | C26: =(-(LOG(A26/100))) -> 0.78251606 | D26: =(500*B26)/10000 -> 2.0306115
A27: 17 | B27: =(C27+$H$19)/$G$20 -> 39.94047 | C27: =(-(LOG(A27/100))) -> 0.76955108 | D27: =(500*B27)/10000 -> 1.9970235
A28: 17.5 | B28: =(C28+$H$19)/$G$20 -> 39.288184 | C28: =(-(LOG(A28/100))) -> 0.75696195 | D28: =(500*B28)/10000 -> 1.9644092
A29: 18 | B29: =(C29+$H$19)/$G$20 -> 38.654274 | C29: =(-(LOG(A29/100))) -> 0.74472749 | D29: =(500*B29)/10000 -> 1.9327137
A30: 18.5 | B30: =(C30+$H$19)/$G$20 -> 38.037734 | C30: =(-(LOG(A30/100))) -> 0.73282827 | D30: =(500*B30)/10000 -> 1.9018867
A31: 19 | B31: =(C31+$H$19)/$G$20 -> 37.437637 | C31: =(-(LOG(A31/100))) -> 0.7212464 | D31: =(500*B31)/10000 -> 1.8718819
A32: 19.5 | B32: =(C32+$H$19)/$G$20 -> 36.853129 | C32: =(-(LOG(A32/100))) -> 0.70996539 | D32: =(500*B32)/10000 -> 1.8426564
... A193: 100 | B193: =(C193+$H$19)/$G$20 -> 0.067357513 | C193: =(-(LOG(A193/100))) -> 0 | D193: =(500*B193)/10000 -> 0.0033678756

Sheet RESULTADOS 
I1: Fertilizantes Tepeyac S.A. de C.V | AD1: Pagina: | AG1: 1 de | AI1: =ROUNDUP(Datos_Cliente!$C$8/4,0) -> 2
I2: Laboratorio de Análisis de Suelo, Agua, Planta y Fertilizante | AD2: Fecha: | AG2: =IF(Datos_Cliente!$G$14<>"", Datos_Cliente!$G$14,"NA") -> 45924
I3: Cd. Obregón, Sonora. CP. 85065 | AD3: Codigo: | AG3: RRP-FT-16
I4: Blvd. Las Torres y Circuito Interior No. 810. Parque Industrial. | AD4: Reporte No: | AH4: =IF(Datos_Cliente!$G$4<>"", Datos_Cliente!$G$4,"NA") -> 0034
I5: Tel: (644)-169-9209, (644)-169-8789, Ext. 2 | AD5: Solicitud: | AH5: =IF(Datos_Cliente!$C$4<>"", Datos_Cliente!$C$4,"NA") -> 2025-0482
I6: www.ftepeyac.com.mx
A8: INFORME DE RESULTADOS DE ANÁLISIS DE PLANTA
A10: Cliente: | E10: =IF(Datos_Cliente!$C$6<>"", Datos_Cliente!$C$6,"NA") -> EL CAUDILLO | Q10: Predio: | T10: =IF(Datos_Cliente!$G$6<>"", Datos_Cliente!$G$6,"NA") -> BLOCK 905 | AA10: Cultivo anterior: | AG10: =IF(Datos_Cliente!$G$7<>"", Datos_Cliente!$G$7,"NA") -> NOGAL
A11: Empresa: | E11: =IF(Datos_Cliente!$C$7<>"", Datos_Cliente!$C$7,"NA") -> EL CAUDILLO | Q11: Riego: | T11: =IF(Datos_Cliente!$G$11<>"", Datos_Cliente!$G$11,"NA") -> GOTEO | AA11: Cultivo actual: | AG11: =IF(Datos_Cliente!$G$8<>"", Datos_Cliente!$G$8,"NA") -> NOGAL
A12: Ubicación: | E12: =IF(Datos_Cliente!$G$5<>"", Datos_Cliente!$G$5,"NA") -> BACUM, SON. | Q12: Etapa: | T12: =IF(Datos_Cliente!$G$9<>"", Datos_Cliente!$G$9,"NA") -> COSECHA | AA12: Recepción: | AG12: =IF(Datos_Cliente!$C$5<>"", Datos_Cliente!$C$5,"NA") -> 45922
A14: No. Laboratorio | L14: =IF(Datos_Cliente!$C$11<>"",Datos_Cliente!$C$11,"NA") -> 2025-0482-1 | Q14: =IF(Datos_Cliente!$C$12<>"",Datos_Cliente!$C$12,"NA") -> 2025-0482-2 | V14: =IF(Datos_Cliente!$C$13<>"",Datos_Cliente!$C$13,"NA") -> 2025-0482-3 | AA14: =IF(Datos_Cliente!$C$14<>"",Datos_Cliente!$C$14,"NA") -> 2025-0482-4
A15: ID muestra | L15: =IF(Datos_Cliente!$B$11<>"",Datos_Cliente!$B$11,"NA") -> 50 HAS 2012 NORTE | Q15: =IF(Datos_Cliente!$B$12<>"",Datos_Cliente!$B$12,"NA") -> 50 HAS 2012 SUR | V15: =IF(Datos_Cliente!$B$13<>"",Datos_Cliente!$B$13,"NA") -> 25 HAS 2014 SUR | AA15: =IF(Datos_Cliente!$B$14<>"",Datos_Cliente!$B$14,"NA") -> 25 HAS 2014 NORTE
A16: ELEMENTOS MAYORES | G16: UNIDADES | L16: RESULTADOS | Q16: RESULTADOS | V16: RESULTADOS | AA16: RESULTADOS | AF16: REFERENCIAS
A17: Nitrógeno total (N) | G17: % | L17: =IF(Lectura_Fert!L11<>"",(Lectura_Fert!L11*Lectura_Fert!$K$8*0.014*100)/Lectura_Fert!K11, "NA") -> 2.59 | Q17: =IF(Lectura_Fert!L12<>"",(Lectura_Fert!L12*Lectura_Fert!$K$8*0.014*100)/Lectura_Fert!K12, "NA") -> 2.52 | V17: =IF(Lectura_Fert!L13<>"",(Lectura_Fert!L13*Lectura_Fert!$K$8*0.014*100)/Lectura_Fert!K13, "NA") -> 2.38 | AA17: =IF(Lectura_Fert!L14<>"",(Lectura_Fert!L14*Lectura_Fert!$K$8*0.014*100)/Lectura_Fert!K14, "NA") -> 2.66 | AF17: =VLOOKUP(Datos_Cliente!$G$16,CULTIVOS!$A$2:$W$127,2,0) -> 2.7 | AH17: a | AI17: =VLOOKUP(Datos_Cliente!$G$16,CULTIVOS!$A$2:$W$127,3,0) -> 3.5
A18: Calcio (Ca) | G18: % | L18: =IF(Lectura_Fert!R11<>"", Lectura_Fert!R11, "NA") -> 3.02 | Q18: =IF(Lectura_Fert!R12<>"", Lectura_Fert!R12, "NA") -> 2.57 | V18: =IF(Lectura_Fert!R13<>"", Lectura_Fert!R13, "NA") -> 2.63 | AA18: =IF(Lectura_Fert!R14<>"", Lectura_Fert!R14, "NA") -> 3.08 | AF18: =VLOOKUP(Datos_Cliente!$G$16,CULTIVOS!$A$2:$W$127,4,0) -> 1 | AH18: a | AI18: =VLOOKUP(Datos_Cliente!$G$16,CULTIVOS!$A$2:$W$127,5,0) -> 1.75
A19: Magnesio (Mg) | G19: % | L19: =IF(Lectura_Fert!S11<>"", Lectura_Fert!S11, "NA") -> 0.63 | Q19: =IF(Lectura_Fert!S12<>"", Lectura_Fert!S12, "NA") -> 0.55 | V19: =IF(Lectura_Fert!S13<>"", Lectura_Fert!S13, "NA") -> 0.54 | AA19: =IF(Lectura_Fert!S14<>"", Lectura_Fert!S14, "NA") -> 0.66 | AF19: =VLOOKUP(Datos_Cliente!$G$16,CULTIVOS!$A$2:$W$127,6,0) -> 0.3 | AH19: a | AI19: =VLOOKUP(Datos_Cliente!$G$16,CULTIVOS!$A$2:$W$127,7,0) -> 0.6
A20: Potasio (K) | G20: % | L20: =IF(Lectura_Fert!Y11<>"", (((Lectura_Fert!Y11-Lectura_Fert!$Y$10)*Lectura_Fert!$T11*Lectura_Fert!$U11))/10000, "NA") -> 0.88 | Q20: =IF(Lectura_Fert!Y12<>"", (((Lectura_Fert!Y12-Lectura_Fert!$Y$10)*Lectura_Fert!$T12*Lectura_Fert!$U12))/10000, "NA") -> 0.8 | V20: =IF(Lectura_Fert!Y13<>"", (((Lectura_Fert!Y13-Lectura_Fert!$Y$10)*Lectura_Fert!$T13*Lectura_Fert!$U13))/10000, "NA") -> 0.8 | AA20: =IF(Lectura_Fert!Y14<>"", (((Lectura_Fert!Y14-Lectura_Fert!$Y$10)*Lectura_Fert!$T14*Lectura_Fert!$U14))/10000, "NA") -> 0.82 | AF20: =VLOOKUP(Datos_Cliente!$G$16,CULTIVOS!$A$2:$W$127,8,0) -> 1.25 | AH20: a | AI20: =VLOOKUP(Datos_Cliente!$G$16,CULTIVOS!$A$2:$W$127,9,0) -> 2.5
A21: Fosforo (P) | G21: % | L21: =IF(Lectura_Fert!J11<>"", (VLOOKUP(Lectura_Fert!J11,P_Aprov!$A$2:$B$193,2)*(100/Lectura_Fert!H11)*(50/Lectura_Fert!I11))/10000, "NA") -> 0.12817866 | Q21: =IF(Lectura_Fert!J12<>"", (VLOOKUP(Lectura_Fert!J12,P_Aprov!$A$2:$B$193,2)*(100/Lectura_Fert!H12)*(50/Lectura_Fert!I12))/10000, "NA") -> 0.1219106 | V21: =IF(Lectura_Fert!J13<>"", (VLOOKUP(Lectura_Fert!J13,P_Aprov!$A$2:$B$193,2)*(100/Lectura_Fert!H13)*(50/Lectura_Fert!I13))/10000, "NA") -> 0.14082054 | AA21: =IF(Lectura_Fert!J14<>"", (VLOOKUP(Lectura_Fert!J14,P_Aprov!$A$2:$B$193,2)*(100/Lectura_Fert!H14)*(50/Lectura_Fert!I14))/10000, "NA") -> 0.13448185 | AF21: =VLOOKUP(Datos_Cliente!$G$16,CULTIVOS!$A$2:$W$127,10,0) -> 0.14 | AH21: a | AI21: =VLOOKUP(Datos_Cliente!$G$16,CULTIVOS!$A$2:$W$127,11,0) -> 0.3
A22: Nitrógeno (N - NO₃) | G22: ppm | L22: =IF(Lectura_Fert!Q11<>"", VLOOKUP(Lectura_Fert!Q11,'N-NO3'!$A$2:$B$187,2)*(Lectura_Fert!N11/Lectura_Fert!M11)*(Lectura_Fert!P11/Lectura_Fert!O11), "NA") -> NA | Q22: =IF(Lectura_Fert!Q12<>"", VLOOKUP(Lectura_Fert!Q12,'N-NO3'!$A$2:$B$187,2)*(Lectura_Fert!N12/Lectura_Fert!M12)*(Lectura_Fert!P12/Lectura_Fert!O12), "NA") -> NA | V22: =IF(Lectura_Fert!Q13<>"", VLOOKUP(Lectura_Fert!Q13,'N-NO3'!$A$2:$B$187,2)*(Lectura_Fert!N13/Lectura_Fert!M13)*(Lectura_Fert!P13/Lectura_Fert!O13), "NA") -> NA | AA22: =IF(Lectura_Fert!Q14<>"", VLOOKUP(Lectura_Fert!Q14,'N-NO3'!$A$2:$B$187,2)*(Lectura_Fert!N14/Lectura_Fert!M14)*(Lectura_Fert!P14/Lectura_Fert!O14), "NA") -> NA | AF22: =VLOOKUP(Datos_Cliente!$G$16,CULTIVOS!$A$2:$W$127,12,0) -> 0 | AH22: a | AI22: =VLOOKUP(Datos_Cliente!$G$16,CULTIVOS!$A$2:$W$127,13,0) -> 0
A23: ELEMENTOS MENORES | G23: UNIDADES | L23: RESULTADOS | Q23: RESULTADOS | V23: RESULTADOS | AA23: RESULTADOS
A24: Hierro (Fe) | G24: ppm | L24: =IF(Lectura_Fert!E11<>"", Lectura_Fert!E11, "NA") -> 168.71 | Q24: =IF(Lectura_Fert!E12<>"", Lectura_Fert!E12, "NA") -> 162.48 | V24: =IF(Lectura_Fert!E13<>"", Lectura_Fert!E13, "NA") -> 168.46 | AA24: =IF(Lectura_Fert!E14<>"", Lectura_Fert!E14, "NA") -> 158.89 | AF24: =VLOOKUP(Datos_Cliente!$G$16,CULTIVOS!$A$2:$W$127,14,0) -> 50 | AH24: a | AI24: =VLOOKUP(Datos_Cliente!$G$16,CULTIVOS!$A$2:$W$127,15,0) -> 300
A25: Manganeso (Mn) | G25: ppm | L25: =IF(Lectura_Fert!D11<>"", Lectura_Fert!D11, "NA") -> 657.22 | Q25: =IF(Lectura_Fert!D12<>"", Lectura_Fert!D12, "NA") -> 563.95 | V25: =IF(Lectura_Fert!D13<>"", Lectura_Fert!D13, "NA") -> 583.2 | AA25: =IF(Lectura_Fert!D14<>"", Lectura_Fert!D14, "NA") -> 614.38 | AF25: =VLOOKUP(Datos_Cliente!$G$16,CULTIVOS!$A$2:$W$127,16,0) -> 80 | AH25: a | AI25: =VLOOKUP(Datos_Cliente!$G$16,CULTIVOS!$A$2:$W$127,17,0) -> 300
A26: Zinc (Zn) | G26: ppm | L26: =IF(Lectura_Fert!F11<>"", Lectura_Fert!F11, "NA") -> 82.26 | Q26: =IF(Lectura_Fert!F12<>"", Lectura_Fert!F12, "NA") -> 116.87 | V26: =IF(Lectura_Fert!F13<>"", Lectura_Fert!F13, "NA") -> 120.3 | AA26: =IF(Lectura_Fert!F14<>"", Lectura_Fert!F14, "NA") -> 131.62 | AF26: =VLOOKUP(Datos_Cliente!$G$16,CULTIVOS!$A$2:$W$127,18,0) -> 50 | AH26: a | AI26: =VLOOKUP(Datos_Cliente!$G$16,CULTIVOS!$A$2:$W$127,19,0) -> 100
A27: Cobre (Cu) | G27: ppm | L27: =IF(Lectura_Fert!C11<>"", Lectura_Fert!C11, "NA") -> 4.88 | Q27: =IF(Lectura_Fert!C12<>"", Lectura_Fert!C12, "NA") -> 4.89 | V27: =IF(Lectura_Fert!C13<>"", Lectura_Fert!C13, "NA") -> 4.8 | AA27: =IF(Lectura_Fert!C14<>"", Lectura_Fert!C14, "NA") -> 4.24 | AF27: =VLOOKUP(Datos_Cliente!$G$16,CULTIVOS!$A$2:$W$127,20,0) -> 6 | AH27: a | AI27: =VLOOKUP(Datos_Cliente!$G$16,CULTIVOS!$A$2:$W$127,21,0) -> 30
A28: Boro (B) | G28: ppm | L28: =IF(Lectura_Fert!G11<>"", VLOOKUP(Lectura_Fert!G11,Boro!$A$2:$C$194,3)*400, "NA") -> 187.67174 | Q28: =IF(Lectura_Fert!G12<>"", VLOOKUP(Lectura_Fert!G12,Boro!$A$2:$C$194,3)*400, "NA") -> 137.04991 | V28: =IF(Lectura_Fert!G13<>"", VLOOKUP(Lectura_Fert!G13,Boro!$A$2:$C$194,3)*400, "NA") -> 146.48691 | AA28: =IF(Lectura_Fert!G14<>"", VLOOKUP(Lectura_Fert!G14,Boro!$A$2:$C$194,3)*400, "NA") -> 171.52903 | AF28: =VLOOKUP(Datos_Cliente!$G$16,CULTIVOS!$A$2:$W$127,22,0) -> 15 | AH28: a | AI28: =VLOOKUP(Datos_Cliente!$G$16,CULTIVOS!$A$2:$W$127,23,0) -> 50
A31: INTERPRETACIÓN Y RECOMENDACIÓN
A33: El análisis foliar de nogal indica que el nitrógeno. potasio, fósforo y cobre se encuentran por debajo de los niveles de suficiencia para el cultivo. Recomendación.- Aplicar al suelo en el riego 20 kg/ha de nitrógeno + 30 L/ha de tiosulfato de potasio. Aparte y sin mezclar aplicar al suelo en el riego 15 L/ha de ácido fosfórico. Aplicar vía foliar 0.2 kg/ha de sulfato de cobre en 200 litros de agua. Continuar con el programa de fertilización establecido para el cultivo realizando los ajustes indicados.
A47: *Cualquier duda o consulta respecto a la interpretacion de resultados y/o recomendación, comunicarse a los telefonos de contacto del laboratorio. (recuadro superior del informe)
N52: Ing. María Mónica Duarte Lobo
I56: Fertilizantes Tepeyac S.A. de C.V | AD56: Pagina: | AG56: 2 de | AI56: =ROUNDUP(Datos_Cliente!$C$8/4,0) -> 2
I57: Laboratorio de Análisis de Suelo, Agua, Planta y Fertilizante | AD57: Fecha: | AG57: =IF(Datos_Cliente!$G$15<>"", Datos_Cliente!$G$15,"NA") -> 45926
I58: Cd. Obregón, Sonora. CP. 85065 | AD58: Reporte No: | AH58: =IF(Datos_Cliente!$G$4<>"", Datos_Cliente!$G$4,"NA") -> 0034
I59: Blvd. Las Torres y Circuito Interior No. 810. Parque Industrial.
I60: Tel: (644)-169-9209, (644)-169-8789, Ext. 2 | AD60: Solicitud: | AH60: =IF(Datos_Cliente!$C$4<>"", Datos_Cliente!$C$4,"NA") -> 2025-0482
I61: www.ftepeyac.com.mx
A63: INFORME DE RESULTADOS DE ANÁLISIS DE PLANTA
A65: Cliente: | E65: =IF(Datos_Cliente!$C$6<>"", Datos_Cliente!$C$6,"NA") -> EL CAUDILLO | Q65: Predio: | T65: =IF(Datos_Cliente!$G$6<>"", Datos_Cliente!$G$6,"NA") -> BLOCK 905 | AA65: Cultivo anterior: | AG65: =IF(Datos_Cliente!$G$7<>"", Datos_Cliente!$G$7,"NA") -> NOGAL
A66: Empresa: | E66: =IF(Datos_Cliente!$C$7<>"", Datos_Cliente!$C$7,"NA") -> EL CAUDILLO | Q66: Riego: | T66: =IF(Datos_Cliente!$G$11<>"", Datos_Cliente!$G$11,"NA") -> GOTEO | AA66: Cultivo actual: | AG66: =IF(Datos_Cliente!$G$8<>"", Datos_Cliente!$G$8,"NA") -> NOGAL
A67: Ubicación: | E67: =IF(Datos_Cliente!$G$5<>"", Datos_Cliente!$G$5,"NA") -> BACUM, SON. | Q67: Etapa: | T67: =IF(Datos_Cliente!$G$9<>"", Datos_Cliente!$G$9,"NA") -> COSECHA | AA67: Recepción: | AG67: =IF(Datos_Cliente!$C$5<>"", Datos_Cliente!$C$5,"NA") -> 45922
A69: No. Laboratorio | L69: =IF(Datos_Cliente!$C$15<>"",Datos_Cliente!$C$15,"NA") -> 2025-0482-5 | Q69: =IF(Datos_Cliente!$C$16<>"",Datos_Cliente!$C$16,"NA") -> 2025-0482-6 | V69: =IF(Datos_Cliente!$C$17<>"",Datos_Cliente!$C$17,"NA") -> NA | AA69: =IF(Datos_Cliente!$C$18<>"",Datos_Cliente!$C$18,"NA") -> NA
...

Sheet CULTIVOS
A1: cultivo/etapa | B1: Nitrógeno total (N) | D1: Calcio (Ca) | F1: Magnesio (Mg) | H1: Potasio (K) | J1: Fosforo (P) | L1: Nitratos (NO₃) | N1: Fierro (Fe) | P1: Manganeso (Mn) | R1: Zinc (Zn) | T1: Cobre (Cu) | V1: Boro (B)
A2: Agave/sin etapa | B2: NA | C2: NA | D2: NA | E2: NA | F2: NA | G2: NA | H2: NA | I2: NA | J2: NA | K2: NA | L2: NA | M2: NA | N2: NA | O2: NA | P2: NA | Q2: NA | R2: NA | S2: NA | T2: NA | U2: NA | V2: NA | W2: NA
A3: Agostadero/sin etapa | B3: NA | C3: NA | D3: NA | E3: NA | F3: NA | G3: NA | H3: NA | I3: NA | J3: NA | K3: NA | L3: NA | M3: NA | N3: NA | O3: NA | P3: NA | Q3: NA | R3: NA | S3: NA | T3: NA | U3: NA | V3: NA | W3: NA
A4: Aguacate/Hojas de 5-7 meses | B4: 1.6 | C4: 2 | D4: 1 | E4: 3 | F4: 0.25 | G4: 0.8 | H4: 0.75 | I4: 2 | J4: 0.08 | K4: 0.25 | L4: 0 | M4: 0 | N4: 50 | O4: 200 | P4: 30 | Q4: 500 | R4: 30 | S4: 150 | T4: 5 | U4: 15 | V4: 50 | W4: 100
A5: Ajonjoli/Vegetativo | B5: 2 | C5: 4.5 | D5: 1 | E5: 3 | F5: 0.2 | G5: 0.75 | H5: 2.9 | I5: 5.1 | J5: 0.28 | K5: 0.69 | L5: 0 | M5: 0 | N5: 30 | O5: 200 | P5: 25 | Q5: 25 | R5: 22 | S5: 50 | T5: 4 | U5: 25 | V5: 15 | W5: 54
A6: Albaca/sin etapa | B6: NA | C6: NA | D6: NA | E6: NA | F6: NA | G6: NA | H6: NA | I6: NA | J6: NA | K6: NA | L6: NA | M6: NA | N6: NA | O6: NA | P6: NA | Q6: NA | R6: NA | S6: NA | T6: NA | U6: NA | V6: NA | W6: NA
A7: Albahaca/Desarrollo | B7: 2.5 | C7: 3.22 | D7: 1.92 | E7: 2.56 | F7: 0.87 | G7: 1.53 | H7: 1.11 | I7: 2.15 | J7: 0.5 | K7: 0.63 | L7: 0 | M7: 0 | N7: 300 | O7: 450 | P7: 120 | Q7: 234 | R7: 40 | S7: 70 | T7: 15 | U7: 25 | V7: 20 | W7: 30
A8: Alcachofa/sin etapa | B8: NA | C8: NA | D8: NA | E8: NA | F8: NA | G8: NA | H8: NA | I8: NA | J8: NA | K8: NA | L8: NA | M8: NA | N8: NA | O8: NA | P8: NA | Q8: NA | R8: NA | S8: NA | T8: NA | U8: NA | V8: NA | W8: NA
A9: Alfalfa/Antes de floración | B9: 4.49 | C9: 5 | D9: 1.79 | E9: 3 | F9: 0.29 | G9: 1 | H9: 1.99 | I9: 3.5 | J9: 0.26 | K9: 0.7 | L9: 0 | M9: 0 | N9: 29 | O9: 250 | P9: 30 | Q9: 100 | R9: 20 | S9: 70 | T9: 7 | U9: 30 | V9: 29 | W9: 80
A10: Algodón/Floracion | B10: 3 | C10: 4.3 | D10: 2.2 | E10: 3.5 | F10: 0.3 | G10: 0.8 | H10: 0.9 | I10: 2 | J10: 0.25 | K10: 0.45 | L10: 7000 | M10: 9000 | N10: 40 | O10: 300 | P10: 30 | Q10: 300 | R10: 20 | S10: 100 | T10: 5 | U10: 25 | V10: 20 | W10: 60
A11: Algodón/Primeros cuadros | B11: 3.5 | C11: 4.5 | D11: 2 | E11: 3 | F11: 0.3 | G11: 0.9 | H11: 1.5 | I11: 3 | J11: 0.3 | K11: 0.5 | L11: 13000 | M11: 16000 | N11: 50 | O11: 250 | P11: 25 | Q11: 350 | R11: 20 | S11: 200 | T11: 5 | U11: 25 | V11: 20 | W11: 60
A12: Arandano/sin etapa | B12: 1.08 | C12: 1.7 | D12: 0.25 | E12: 0.75 | F12: 0.13 | G12: 0.22 | H12: 0.3 | I12: 0.6 | J12: 0.07 | K12: 0.2 | L12: 0 | M12: 0 | N12: 27 | O12: 85 | P12: 25 | Q12: 150 | R12: 10 | S12: 25 | T12: 4 | U12: 10 | V12: 12 | W12: 35
A13: Arboles maderables/sin etapa | B13: NA | C13: NA | D13: NA | E13: NA | F13: NA | G13: NA | H13: NA | I13: NA | J13: NA | K13: NA | L13: NA | M13: NA | N13: NA | O13: NA | P13: NA | Q13: NA | R13: NA | S13: NA | T13: NA | U13: NA | V13: NA | W13: NA
A14: Blue berry/Desarrollo | B14: 1.08 | C14: 1.7 | D14: 0.25 | E14: 0.75 | F14: 0.13 | G14: 0.22 | H14: 0.3 | I14: 0.6 | J14: 0.07 | K14: 0.2 | L14: 0 | M14: 0 | N14: 27 | O14: 85 | P14: 25 | Q14: 150 | R14: 10 | S14: 25 | T14: 4 | U14: 10 | V14: 12 | W14: 35
A15: Brocoli/Inicio cabezuelas | B15: 3.19 | C15: 5.5 | D15: 0.99 | E15: 2.5 | F15: 0.24 | G15: 0.75 | H15: 1.99 | I15: 4 | J15: 0.29 | K15: 0.75 | L15: 8000 | M15: 15000 | N15: 69 | O15: 300 | P15: 24 | Q15: 200 | R15: 34 | S15: 200 | T15: 5 | U15: 15 | V15: 29 | W15: 100
A16: calabaza cabocha/sin etapa | B16: NA | C16: NA | D16: NA | E16: NA | F16: NA | G16: NA | H16: NA | I16: NA | J16: NA | K16: NA | L16: NA | M16: NA | N16: NA | O16: NA | P16: NA | Q16: NA | R16: NA | S16: NA | T16: NA | U16: NA | V16: NA | W16: NA
A17: Calabaza/Floración producción | B17: 4 | C17: 6 | D17: 1.2 | E17: 2.5 | F17: 0.3 | G17: 1 | H17: 3 | I17: 5 | J17: 0.3 | K17: 0.5 | L17: 12000 | M17: 15000 | N17: 50 | O17: 200 | P17: 50 | Q17: 250 | R17: 20 | S17: 200 | T17: 7 | U17: 20 | V17: 25 | W17: 75
A18: Campo de golf/sin etapa | B18: NA | C18: NA | D18: NA | E18: NA | F18: NA | G18: NA | H18: NA | I18: NA | J18: NA | K18: NA | L18: NA | M18: NA | N18: NA | O18: NA | P18: NA | Q18: NA | R18: NA | S18: NA | T18: NA | U18: NA | V18: NA | W18: NA
A19: Cartamo/Des veg floración | B19: 2 | C19: 4.5 | D19: 1 | E19: 3 | F19: 0.2 | G19: 0.75 | H19: 2.9 | I19: 5.1 | J19: 0.28 | K19: 0.69 | L19: 0 | M19: 0 | N19: 30 | O19: 200 | P19: 25 | Q19: 250 | R19: 22 | S19: 49 | T19: 4 | U19: 25 | V19: 15 | W19: 54
A20: Cebolla /1/2 de crecimiento de madurez | B20: 4.5 | C20: 5.5 | D20: 0.5 | E20: 2.2 | F20: 0.25 | G20: 0.4 | H20: 3.5 | I20: 5 | J20: 0.3 | K20: 0.45 | L20: 0 | M20: 0 | N20: 60 | O20: 300 | P20: 50 | Q20: 250 | R20: 25 | S20: 100 | T20: 15 | U20: 35 | V20: 25 | W20: 75
A21: Cebolla/Bulbo | B21: 3.4 | C21: 4.5 | D21: 1 | E21: 1.8 | F21: 0.23 | G21: 0.3 | H21: 3 | I21: 4.5 | J21: 0.28 | K21: 0.5 | L21: 0 | M21: 0 | N21: 60 | O21: 300 | P21: 50 | Q21: 250 | R21: 25 | S21: 100 | T21: 15 | U21: 35 | V21: 25 | W21: 75
A22: Cebolla/des veg | B22: 5 | C22: 6 | D22: 1 | E22: 3.5 | F22: 0.3 | G22: 0.5 | H22: 4 | I22: 5.5 | J22: 0.35 | K22: 0.5 | L22: 5000 | M22: 8000 | N22: 60 | O22: 300 | P22: 50 | Q22: 250 | R22: 25 | S22: 100 | T22: 15 | U22: 35 | V22: 22 | W22: 60
A23: Cesped/sin etapa | B23: NA | C23: NA | D23: NA | E23: NA | F23: NA | G23: NA | H23: NA | I23: NA | J23: NA | K23: NA | L23: NA | M23: NA | N23: NA | O23: NA | P23: NA | Q23: NA | R23: NA | S23: NA | T23: NA | U23: NA | V23: NA | W23: NA
A24: Chicharo/Floracion chicharos | B24: 4 | C24: 5 | D24: 1.2 | E24: 2 | F24: 0.3 | G24: 0.7 | H24: 2 | I24: 3.5 | J24: 0.3 | K24: 0.8 | L24: 0 | M24: 0 | N24: 50 | O24: 300 | P24: 25 | Q24: 400 | R24: 25 | S24: 400 | T24: 7 | U24: 100 | V24: 5 | W24: 60
A25: Chicharo/Producción de chicharos | B25: 4.75 | C25: 6.75 | D25: 1.78 | E25: 2.1 | F25: 0.27 | G25: 0.7 | H25: 4.4 | I25: 5.5 | J25: 0.26 | K25: 0.46 | L25: 0 | M25: 0 | N25: 26 | O25: 70 | P25: 43 | Q25: 400 | R25: 28 | S25: 400 | T25: 13 | U25: 25 | V25: 10 | W25: 15
A26: Chile ancho/sin etapa | B26: NA | C26: NA | D26: NA | E26: NA | F26: NA | G26: NA | H26: NA | I26: NA | J26: NA | K26: NA | L26: NA | M26: NA | N26: NA | O26: NA | P26: NA | Q26: NA | R26: NA | S26: NA | T26: NA | U26: NA | V26: NA | W26: NA
A27: Chile cayenne/Des veg-flor | B27: 4 | C27: 6 | D27: 1 | E27: 2.5 | F27: 0.3 | G27: 1 | H27: 4 | I27: 6 | J27: 0.35 | K27: 1 | L27: 7000 | M27: 10000 | N27: 60 | O27: 300 | P27: 50 | Q27: 250 | R27: 20 | S27: 200 | T27: 6 | U27: 25 | V27: 25 | W27: 75
A28: Chile cayenne/Fruct - cosecha | B28: 3.5 | C28: 5 | D28: 1.3 | E28: 2.8 | F28: 0.3 | G28: 1 | H28: 3.5 | I28: 4.5 | J28: 0.22 | K28: 0.7 | L28: 5000 | M28: 8000 | N28: 60 | O28: 300 | P28: 50 | Q28: 250 | R28: 20 | S28: 200 | T28: 6 | U28: 25 | V28: 25 | W28: 75
A29: Chile habanero/Floracion | B29: 3.5 | C29: 5 | D29: 1.3 | E29: 2.8 | F29: 0.3 | G29: 1 | H29: 3.5 | I29: 4.5 | J29: 0.21 | K29: 0.7 | L29: 5000 | M29: 9000 | N29: 60 | O29: 300 | P29: 25 | Q29: 250 | R29: 20 | S29: 200 | T29: 5 | U29: 25 | V29: 25 | W29: 75
A30: Chile pace/sin etapa | B30: NA | C30: NA | D30: NA | E30: NA | F30: NA | G30: NA | H30: NA | I30: NA | J30: NA | K30: NA | L30: NA | M30: NA | N30: NA | O30: NA | P30: NA | Q30: NA | R30: NA | S30: NA | T30: NA | U30: NA | V30: NA | W30: NA
A31: Chile poblano/Des vef - flor | B31: 3 | C31: 3.4 | D31: 1.1 | E31: 4 | F31: 0.17 | G31: 0.44 | H31: 0.9 | I31: 1.1 | J31: 0.15 | K31: 0.25 | L31: 0 | M31: 0 | N31: 60 | O31: 150 | P31: 25 | Q31: 200 | R31: 5 | S31: 30 | T31: 5 | U31: 30 | V31: 30 | W31: 100
A32: Chile poblano/Peq frutus cosecha | B32: 3.5 | C32: 5 | D32: 1.3 | E32: 2.8 | F32: 0.3 | G32: 1 | H32: 3.5 | I32: 4.5 | J32: 0.22 | K32: 0.7 | L32: 5000 | M32: 8000 | N32: 60 | O32: 300 | P32: 50 | Q32: 250 | R32: 20 | S32: 200 | T32: 5 | U32: 25 | V32: 25 | W32: 75
A33: Chile verde anaheim/Floracion-prod | B33: 3.5 | C33: 5 | D33: 1.3 | E33: 2.8 | F33: 0.3 | G33: 1 | H33: 3.5 | I33: 4.5 | J33: 0.21 | K33: 0.7 | L33: 5000 | M33: 8000 | N33: 60 | O33: 300 | P33: 50 | Q33: 250 | R33: 20 | S33: 200 | T33: 5 | U33: 25 | V33: 25 | W33: 75
A34: Chile/Flor inicio frut | B34: 4 | C34: 6 | D34: 1 | E34: 2.5 | F34: 0.3 | G34: 1 | H34: 4 | I34: 6 | J34: 0.35 | K34: 1 | L34: 5000 | M34: 8000 | N34: 60 | O34: 300 | P34: 50 | Q34: 250 | R34: 20 | S34: 200 | T34: 5 | U34: 25 | V34: 25 | W34: 75
A35: Chile/Floracion fructificacion | B35: 4 | C35: 6 | D35: 1 | E35: 2.5 | F35: 0.3 | G35: 1 | H35: 4 | I35: 6 | J35: 0.35 | K35: 1 | L35: 7000 | M35: 10000 | N35: 60 | O35: 300 | P35: 50 | Q35: 250 | R35: 20 | S35: 200 | T35: 6 | U35: 20 | V35: 25 | W35: 75
A36: Chile/Fructi cosecha | B36: 3.5 | C36: 5 | D36: 1.3 | E36: 2.8 | F36: 0.3 | G36: 1 | H36: 3.5 | I36: 4.5 | J36: 0.22 | K36: 0.7 | L36: 5000 | M36: 8000 | N36: 60 | O36: 300 | P36: 50 | Q36: 250 | R36: 20 | S36: 200 | T36: 5 | U36: 25 | V36: 25 | W36: 75
A37: Chile/Fructificacion cosecha | B37: 3.5 | C37: 5 | D37: 1.3 | E37: 2.8 | F37: 0.3 | G37: 1 | H37: 3.5 | I37: 4.5 | J37: 0.21 | K37: 0.7 | L37: 5000 | M37: 8000 | N37: 60 | O37: 300 | P37: 50 | Q37: 250 | R37: 20 | S37: 200 | T37: 5 | U37: 25 | V37: 25 | W37: 75
A38: Chile/Pequenos frutos cosecha | B38: 3.5 | C38: 5 | D38: 1.3 | E38: 2.8 | F38: 0.3 | G38: 1 | H38: 3.5 | I38: 4.5 | J38: 0.22 | K38: 0.7 | L38: 5000 | M38: 8000 | N38: 60 | O38: 300 | P38: 50 | Q38: 250 | R38: 20 | S38: 200 | T38: 6 | U38: 25 | V38: 25 | W38: 75
A39: Citricos/sin etapa | B39: NA | C39: NA | D39: NA | E39: NA | F39: NA | G39: NA | H39: NA | I39: NA | J39: NA | K39: NA | L39: NA | M39: NA | N39: NA | O39: NA | P39: NA | Q39: NA | R39: NA | S39: NA | T39: NA | U39: NA | V39: NA | W39: NA
A40: Descanso/sin etapa | B40: NA | C40: NA | D40: NA | E40: NA | F40: NA | G40: NA | H40: NA | I40: NA | J40: NA | K40: NA | L40: NA | M40: NA | N40: NA | O40: NA | P40: NA | Q40: NA | R40: NA | S40: NA | T40: NA | U40: NA | V40: NA | W40: NA
...
